from django.core.exceptions import ValidationError
from django.db import models


class Route(models.Model):
    id = models.AutoField(primary_key=True, verbose_name='ID')
    name = models.CharField(max_length=64, unique=True, verbose_name="Route's name")
    travel_duration = models.PositiveSmallIntegerField(verbose_name='Trip duration')
    startpoint = models.ForeignKey('cities.City', on_delete=models.CASCADE, related_name='trip_startpoint_set',
                                   verbose_name='Trip starts from:')
    endpoint = models.ForeignKey('cities.City', on_delete=models.CASCADE, related_name='trip_endpoint_set',
                                 verbose_name='Trip ends at:')
    trains = models.ManyToManyField('trains.Train', verbose_name="List of trains")

    class Meta:
        verbose_name = "Route"
        verbose_name_plural = "Routes"
        ordering = ['startpoint', 'endpoint', 'name', ]

    def __str__(self):
        return f'Route â„–{self.name} from {self.startpoint} to {self.endpoint}'
